<?xml version="1.0" encoding="UTF-8"?>
<testng-results skipped="6" failed="2" total="8" passed="0">
  <reporter-output>
  </reporter-output>
  <suite name="Default suite" duration-ms="126" started-at="2020-08-22T09:43:45Z" finished-at="2020-08-22T09:43:45Z">
    <groups>
    </groups>
    <test name="Default test" duration-ms="126" started-at="2020-08-22T09:43:45Z" finished-at="2020-08-22T09:43:45Z">
      <class name="usingretryAnalyzer.MyTest">
        <test-method status="SKIP" signature="Test1()[pri:0, instance:usingretryAnalyzer.MyTest@7946e1f4]" name="Test1" duration-ms="21" started-at="2020-08-22T15:13:45Z" finished-at="2020-08-22T15:13:45Z">
          <exception class="junit.framework.AssertionFailedError">
            <message>
              <![CDATA[expected:<false> but was:<true>]]>
            </message>
            <full-stacktrace>
              <![CDATA[junit.framework.AssertionFailedError: expected:<false> but was:<true>
	at junit.framework.Assert.fail(Assert.java:47)
	at junit.framework.Assert.failNotEquals(Assert.java:282)
	at junit.framework.Assert.assertEquals(Assert.java:64)
	at junit.framework.Assert.assertEquals(Assert.java:149)
	at junit.framework.Assert.assertEquals(Assert.java:155)
	at usingretryAnalyzer.MyTest.Test1(MyTest.java:11)
	at sun.reflect.NativeMethodAccessorImpl.invoke0(Native Method)
	at sun.reflect.NativeMethodAccessorImpl.invoke(Unknown Source)
	at sun.reflect.DelegatingMethodAccessorImpl.invoke(Unknown Source)
	at java.lang.reflect.Method.invoke(Unknown Source)
	at org.testng.internal.MethodInvocationHelper.invokeMethod(MethodInvocationHelper.java:86)
	at org.testng.internal.Invoker.invokeMethod(Invoker.java:646)
	at org.testng.internal.Invoker.invokeTestMethod(Invoker.java:823)
	at org.testng.internal.Invoker.invokeTestMethods(Invoker.java:1131)
	at org.testng.internal.TestMethodWorker.invokeTestMethods(TestMethodWorker.java:129)
	at org.testng.internal.TestMethodWorker.run(TestMethodWorker.java:112)
	at org.testng.TestRunner.privateRun(TestRunner.java:778)
	at org.testng.TestRunner.run(TestRunner.java:632)
	at org.testng.SuiteRunner.runTest(SuiteRunner.java:366)
	at org.testng.SuiteRunner.runSequentially(SuiteRunner.java:361)
	at org.testng.SuiteRunner.privateRun(SuiteRunner.java:319)
	at org.testng.SuiteRunner.run(SuiteRunner.java:268)
	at org.testng.SuiteRunnerWorker.runSuite(SuiteRunnerWorker.java:52)
	at org.testng.SuiteRunnerWorker.run(SuiteRunnerWorker.java:86)
	at org.testng.TestNG.runSuitesSequentially(TestNG.java:1225)
	at org.testng.TestNG.runSuitesLocally(TestNG.java:1150)
	at org.testng.TestNG.runSuites(TestNG.java:1075)
	at org.testng.TestNG.run(TestNG.java:1047)
	at org.testng.remote.AbstractRemoteTestNG.run(AbstractRemoteTestNG.java:126)
	at org.testng.remote.RemoteTestNG.initAndRun(RemoteTestNG.java:137)
	at org.testng.remote.RemoteTestNG.main(RemoteTestNG.java:58)
]]>
            </full-stacktrace>
          </exception> <!-- junit.framework.AssertionFailedError -->
          <reporter-output>
          </reporter-output>
        </test-method> <!-- Test1 -->
        <test-method status="SKIP" signature="Test1()[pri:0, instance:usingretryAnalyzer.MyTest@7946e1f4]" name="Test1" duration-ms="6" started-at="2020-08-22T15:13:45Z" finished-at="2020-08-22T15:13:45Z">
          <exception class="junit.framework.AssertionFailedError">
            <message>
              <![CDATA[expected:<false> but was:<true>]]>
            </message>
            <full-stacktrace>
              <![CDATA[junit.framework.AssertionFailedError: expected:<false> but was:<true>
	at junit.framework.Assert.fail(Assert.java:47)
	at junit.framework.Assert.failNotEquals(Assert.java:282)
	at junit.framework.Assert.assertEquals(Assert.java:64)
	at junit.framework.Assert.assertEquals(Assert.java:149)
	at junit.framework.Assert.assertEquals(Assert.java:155)
	at usingretryAnalyzer.MyTest.Test1(MyTest.java:11)
	at sun.reflect.NativeMethodAccessorImpl.invoke0(Native Method)
	at sun.reflect.NativeMethodAccessorImpl.invoke(Unknown Source)
	at sun.reflect.DelegatingMethodAccessorImpl.invoke(Unknown Source)
	at java.lang.reflect.Method.invoke(Unknown Source)
	at org.testng.internal.MethodInvocationHelper.invokeMethod(MethodInvocationHelper.java:86)
	at org.testng.internal.Invoker.invokeMethod(Invoker.java:646)
	at org.testng.internal.Invoker.retryFailed(Invoker.java:970)
	at org.testng.internal.Invoker.invokeTestMethods(Invoker.java:1149)
	at org.testng.internal.TestMethodWorker.invokeTestMethods(TestMethodWorker.java:129)
	at org.testng.internal.TestMethodWorker.run(TestMethodWorker.java:112)
	at org.testng.TestRunner.privateRun(TestRunner.java:778)
	at org.testng.TestRunner.run(TestRunner.java:632)
	at org.testng.SuiteRunner.runTest(SuiteRunner.java:366)
	at org.testng.SuiteRunner.runSequentially(SuiteRunner.java:361)
	at org.testng.SuiteRunner.privateRun(SuiteRunner.java:319)
	at org.testng.SuiteRunner.run(SuiteRunner.java:268)
	at org.testng.SuiteRunnerWorker.runSuite(SuiteRunnerWorker.java:52)
	at org.testng.SuiteRunnerWorker.run(SuiteRunnerWorker.java:86)
	at org.testng.TestNG.runSuitesSequentially(TestNG.java:1225)
	at org.testng.TestNG.runSuitesLocally(TestNG.java:1150)
	at org.testng.TestNG.runSuites(TestNG.java:1075)
	at org.testng.TestNG.run(TestNG.java:1047)
	at org.testng.remote.AbstractRemoteTestNG.run(AbstractRemoteTestNG.java:126)
	at org.testng.remote.RemoteTestNG.initAndRun(RemoteTestNG.java:137)
	at org.testng.remote.RemoteTestNG.main(RemoteTestNG.java:58)
]]>
            </full-stacktrace>
          </exception> <!-- junit.framework.AssertionFailedError -->
          <reporter-output>
          </reporter-output>
        </test-method> <!-- Test1 -->
        <test-method status="SKIP" signature="Test1()[pri:0, instance:usingretryAnalyzer.MyTest@7946e1f4]" name="Test1" duration-ms="2" started-at="2020-08-22T15:13:45Z" finished-at="2020-08-22T15:13:45Z">
          <exception class="junit.framework.AssertionFailedError">
            <message>
              <![CDATA[expected:<false> but was:<true>]]>
            </message>
            <full-stacktrace>
              <![CDATA[junit.framework.AssertionFailedError: expected:<false> but was:<true>
	at junit.framework.Assert.fail(Assert.java:47)
	at junit.framework.Assert.failNotEquals(Assert.java:282)
	at junit.framework.Assert.assertEquals(Assert.java:64)
	at junit.framework.Assert.assertEquals(Assert.java:149)
	at junit.framework.Assert.assertEquals(Assert.java:155)
	at usingretryAnalyzer.MyTest.Test1(MyTest.java:11)
	at sun.reflect.NativeMethodAccessorImpl.invoke0(Native Method)
	at sun.reflect.NativeMethodAccessorImpl.invoke(Unknown Source)
	at sun.reflect.DelegatingMethodAccessorImpl.invoke(Unknown Source)
	at java.lang.reflect.Method.invoke(Unknown Source)
	at org.testng.internal.MethodInvocationHelper.invokeMethod(MethodInvocationHelper.java:86)
	at org.testng.internal.Invoker.invokeMethod(Invoker.java:646)
	at org.testng.internal.Invoker.retryFailed(Invoker.java:970)
	at org.testng.internal.Invoker.invokeTestMethods(Invoker.java:1149)
	at org.testng.internal.TestMethodWorker.invokeTestMethods(TestMethodWorker.java:129)
	at org.testng.internal.TestMethodWorker.run(TestMethodWorker.java:112)
	at org.testng.TestRunner.privateRun(TestRunner.java:778)
	at org.testng.TestRunner.run(TestRunner.java:632)
	at org.testng.SuiteRunner.runTest(SuiteRunner.java:366)
	at org.testng.SuiteRunner.runSequentially(SuiteRunner.java:361)
	at org.testng.SuiteRunner.privateRun(SuiteRunner.java:319)
	at org.testng.SuiteRunner.run(SuiteRunner.java:268)
	at org.testng.SuiteRunnerWorker.runSuite(SuiteRunnerWorker.java:52)
	at org.testng.SuiteRunnerWorker.run(SuiteRunnerWorker.java:86)
	at org.testng.TestNG.runSuitesSequentially(TestNG.java:1225)
	at org.testng.TestNG.runSuitesLocally(TestNG.java:1150)
	at org.testng.TestNG.runSuites(TestNG.java:1075)
	at org.testng.TestNG.run(TestNG.java:1047)
	at org.testng.remote.AbstractRemoteTestNG.run(AbstractRemoteTestNG.java:126)
	at org.testng.remote.RemoteTestNG.initAndRun(RemoteTestNG.java:137)
	at org.testng.remote.RemoteTestNG.main(RemoteTestNG.java:58)
]]>
            </full-stacktrace>
          </exception> <!-- junit.framework.AssertionFailedError -->
          <reporter-output>
          </reporter-output>
        </test-method> <!-- Test1 -->
        <test-method status="FAIL" signature="Test1()[pri:0, instance:usingretryAnalyzer.MyTest@7946e1f4]" name="Test1" duration-ms="2" started-at="2020-08-22T15:13:45Z" finished-at="2020-08-22T15:13:45Z">
          <exception class="junit.framework.AssertionFailedError">
            <message>
              <![CDATA[expected:<false> but was:<true>]]>
            </message>
            <full-stacktrace>
              <![CDATA[junit.framework.AssertionFailedError: expected:<false> but was:<true>
	at junit.framework.Assert.fail(Assert.java:47)
	at junit.framework.Assert.failNotEquals(Assert.java:282)
	at junit.framework.Assert.assertEquals(Assert.java:64)
	at junit.framework.Assert.assertEquals(Assert.java:149)
	at junit.framework.Assert.assertEquals(Assert.java:155)
	at usingretryAnalyzer.MyTest.Test1(MyTest.java:11)
	at sun.reflect.NativeMethodAccessorImpl.invoke0(Native Method)
	at sun.reflect.NativeMethodAccessorImpl.invoke(Unknown Source)
	at sun.reflect.DelegatingMethodAccessorImpl.invoke(Unknown Source)
	at java.lang.reflect.Method.invoke(Unknown Source)
	at org.testng.internal.MethodInvocationHelper.invokeMethod(MethodInvocationHelper.java:86)
	at org.testng.internal.Invoker.invokeMethod(Invoker.java:646)
	at org.testng.internal.Invoker.retryFailed(Invoker.java:970)
	at org.testng.internal.Invoker.invokeTestMethods(Invoker.java:1149)
	at org.testng.internal.TestMethodWorker.invokeTestMethods(TestMethodWorker.java:129)
	at org.testng.internal.TestMethodWorker.run(TestMethodWorker.java:112)
	at org.testng.TestRunner.privateRun(TestRunner.java:778)
	at org.testng.TestRunner.run(TestRunner.java:632)
	at org.testng.SuiteRunner.runTest(SuiteRunner.java:366)
	at org.testng.SuiteRunner.runSequentially(SuiteRunner.java:361)
	at org.testng.SuiteRunner.privateRun(SuiteRunner.java:319)
	at org.testng.SuiteRunner.run(SuiteRunner.java:268)
	at org.testng.SuiteRunnerWorker.runSuite(SuiteRunnerWorker.java:52)
	at org.testng.SuiteRunnerWorker.run(SuiteRunnerWorker.java:86)
	at org.testng.TestNG.runSuitesSequentially(TestNG.java:1225)
	at org.testng.TestNG.runSuitesLocally(TestNG.java:1150)
	at org.testng.TestNG.runSuites(TestNG.java:1075)
	at org.testng.TestNG.run(TestNG.java:1047)
	at org.testng.remote.AbstractRemoteTestNG.run(AbstractRemoteTestNG.java:126)
	at org.testng.remote.RemoteTestNG.initAndRun(RemoteTestNG.java:137)
	at org.testng.remote.RemoteTestNG.main(RemoteTestNG.java:58)
]]>
            </full-stacktrace>
          </exception> <!-- junit.framework.AssertionFailedError -->
          <reporter-output>
          </reporter-output>
        </test-method> <!-- Test1 -->
        <test-method status="SKIP" signature="Test2()[pri:0, instance:usingretryAnalyzer.MyTest@7946e1f4]" name="Test2" duration-ms="5" started-at="2020-08-22T15:13:45Z" finished-at="2020-08-22T15:13:45Z">
          <exception class="junit.framework.AssertionFailedError">
            <message>
              <![CDATA[expected:<false> but was:<true>]]>
            </message>
            <full-stacktrace>
              <![CDATA[junit.framework.AssertionFailedError: expected:<false> but was:<true>
	at junit.framework.Assert.fail(Assert.java:47)
	at junit.framework.Assert.failNotEquals(Assert.java:282)
	at junit.framework.Assert.assertEquals(Assert.java:64)
	at junit.framework.Assert.assertEquals(Assert.java:149)
	at junit.framework.Assert.assertEquals(Assert.java:155)
	at usingretryAnalyzer.MyTest.Test2(MyTest.java:16)
	at sun.reflect.NativeMethodAccessorImpl.invoke0(Native Method)
	at sun.reflect.NativeMethodAccessorImpl.invoke(Unknown Source)
	at sun.reflect.DelegatingMethodAccessorImpl.invoke(Unknown Source)
	at java.lang.reflect.Method.invoke(Unknown Source)
	at org.testng.internal.MethodInvocationHelper.invokeMethod(MethodInvocationHelper.java:86)
	at org.testng.internal.Invoker.invokeMethod(Invoker.java:646)
	at org.testng.internal.Invoker.invokeTestMethod(Invoker.java:823)
	at org.testng.internal.Invoker.invokeTestMethods(Invoker.java:1131)
	at org.testng.internal.TestMethodWorker.invokeTestMethods(TestMethodWorker.java:129)
	at org.testng.internal.TestMethodWorker.run(TestMethodWorker.java:112)
	at org.testng.TestRunner.privateRun(TestRunner.java:778)
	at org.testng.TestRunner.run(TestRunner.java:632)
	at org.testng.SuiteRunner.runTest(SuiteRunner.java:366)
	at org.testng.SuiteRunner.runSequentially(SuiteRunner.java:361)
	at org.testng.SuiteRunner.privateRun(SuiteRunner.java:319)
	at org.testng.SuiteRunner.run(SuiteRunner.java:268)
	at org.testng.SuiteRunnerWorker.runSuite(SuiteRunnerWorker.java:52)
	at org.testng.SuiteRunnerWorker.run(SuiteRunnerWorker.java:86)
	at org.testng.TestNG.runSuitesSequentially(TestNG.java:1225)
	at org.testng.TestNG.runSuitesLocally(TestNG.java:1150)
	at org.testng.TestNG.runSuites(TestNG.java:1075)
	at org.testng.TestNG.run(TestNG.java:1047)
	at org.testng.remote.AbstractRemoteTestNG.run(AbstractRemoteTestNG.java:126)
	at org.testng.remote.RemoteTestNG.initAndRun(RemoteTestNG.java:137)
	at org.testng.remote.RemoteTestNG.main(RemoteTestNG.java:58)
]]>
            </full-stacktrace>
          </exception> <!-- junit.framework.AssertionFailedError -->
          <reporter-output>
          </reporter-output>
        </test-method> <!-- Test2 -->
        <test-method status="SKIP" signature="Test2()[pri:0, instance:usingretryAnalyzer.MyTest@7946e1f4]" name="Test2" duration-ms="1" started-at="2020-08-22T15:13:45Z" finished-at="2020-08-22T15:13:45Z">
          <exception class="junit.framework.AssertionFailedError">
            <message>
              <![CDATA[expected:<false> but was:<true>]]>
            </message>
            <full-stacktrace>
              <![CDATA[junit.framework.AssertionFailedError: expected:<false> but was:<true>
	at junit.framework.Assert.fail(Assert.java:47)
	at junit.framework.Assert.failNotEquals(Assert.java:282)
	at junit.framework.Assert.assertEquals(Assert.java:64)
	at junit.framework.Assert.assertEquals(Assert.java:149)
	at junit.framework.Assert.assertEquals(Assert.java:155)
	at usingretryAnalyzer.MyTest.Test2(MyTest.java:16)
	at sun.reflect.NativeMethodAccessorImpl.invoke0(Native Method)
	at sun.reflect.NativeMethodAccessorImpl.invoke(Unknown Source)
	at sun.reflect.DelegatingMethodAccessorImpl.invoke(Unknown Source)
	at java.lang.reflect.Method.invoke(Unknown Source)
	at org.testng.internal.MethodInvocationHelper.invokeMethod(MethodInvocationHelper.java:86)
	at org.testng.internal.Invoker.invokeMethod(Invoker.java:646)
	at org.testng.internal.Invoker.retryFailed(Invoker.java:970)
	at org.testng.internal.Invoker.invokeTestMethods(Invoker.java:1149)
	at org.testng.internal.TestMethodWorker.invokeTestMethods(TestMethodWorker.java:129)
	at org.testng.internal.TestMethodWorker.run(TestMethodWorker.java:112)
	at org.testng.TestRunner.privateRun(TestRunner.java:778)
	at org.testng.TestRunner.run(TestRunner.java:632)
	at org.testng.SuiteRunner.runTest(SuiteRunner.java:366)
	at org.testng.SuiteRunner.runSequentially(SuiteRunner.java:361)
	at org.testng.SuiteRunner.privateRun(SuiteRunner.java:319)
	at org.testng.SuiteRunner.run(SuiteRunner.java:268)
	at org.testng.SuiteRunnerWorker.runSuite(SuiteRunnerWorker.java:52)
	at org.testng.SuiteRunnerWorker.run(SuiteRunnerWorker.java:86)
	at org.testng.TestNG.runSuitesSequentially(TestNG.java:1225)
	at org.testng.TestNG.runSuitesLocally(TestNG.java:1150)
	at org.testng.TestNG.runSuites(TestNG.java:1075)
	at org.testng.TestNG.run(TestNG.java:1047)
	at org.testng.remote.AbstractRemoteTestNG.run(AbstractRemoteTestNG.java:126)
	at org.testng.remote.RemoteTestNG.initAndRun(RemoteTestNG.java:137)
	at org.testng.remote.RemoteTestNG.main(RemoteTestNG.java:58)
]]>
            </full-stacktrace>
          </exception> <!-- junit.framework.AssertionFailedError -->
          <reporter-output>
          </reporter-output>
        </test-method> <!-- Test2 -->
        <test-method status="SKIP" signature="Test2()[pri:0, instance:usingretryAnalyzer.MyTest@7946e1f4]" name="Test2" duration-ms="2" started-at="2020-08-22T15:13:45Z" finished-at="2020-08-22T15:13:45Z">
          <exception class="junit.framework.AssertionFailedError">
            <message>
              <![CDATA[expected:<false> but was:<true>]]>
            </message>
            <full-stacktrace>
              <![CDATA[junit.framework.AssertionFailedError: expected:<false> but was:<true>
	at junit.framework.Assert.fail(Assert.java:47)
	at junit.framework.Assert.failNotEquals(Assert.java:282)
	at junit.framework.Assert.assertEquals(Assert.java:64)
	at junit.framework.Assert.assertEquals(Assert.java:149)
	at junit.framework.Assert.assertEquals(Assert.java:155)
	at usingretryAnalyzer.MyTest.Test2(MyTest.java:16)
	at sun.reflect.NativeMethodAccessorImpl.invoke0(Native Method)
	at sun.reflect.NativeMethodAccessorImpl.invoke(Unknown Source)
	at sun.reflect.DelegatingMethodAccessorImpl.invoke(Unknown Source)
	at java.lang.reflect.Method.invoke(Unknown Source)
	at org.testng.internal.MethodInvocationHelper.invokeMethod(MethodInvocationHelper.java:86)
	at org.testng.internal.Invoker.invokeMethod(Invoker.java:646)
	at org.testng.internal.Invoker.retryFailed(Invoker.java:970)
	at org.testng.internal.Invoker.invokeTestMethods(Invoker.java:1149)
	at org.testng.internal.TestMethodWorker.invokeTestMethods(TestMethodWorker.java:129)
	at org.testng.internal.TestMethodWorker.run(TestMethodWorker.java:112)
	at org.testng.TestRunner.privateRun(TestRunner.java:778)
	at org.testng.TestRunner.run(TestRunner.java:632)
	at org.testng.SuiteRunner.runTest(SuiteRunner.java:366)
	at org.testng.SuiteRunner.runSequentially(SuiteRunner.java:361)
	at org.testng.SuiteRunner.privateRun(SuiteRunner.java:319)
	at org.testng.SuiteRunner.run(SuiteRunner.java:268)
	at org.testng.SuiteRunnerWorker.runSuite(SuiteRunnerWorker.java:52)
	at org.testng.SuiteRunnerWorker.run(SuiteRunnerWorker.java:86)
	at org.testng.TestNG.runSuitesSequentially(TestNG.java:1225)
	at org.testng.TestNG.runSuitesLocally(TestNG.java:1150)
	at org.testng.TestNG.runSuites(TestNG.java:1075)
	at org.testng.TestNG.run(TestNG.java:1047)
	at org.testng.remote.AbstractRemoteTestNG.run(AbstractRemoteTestNG.java:126)
	at org.testng.remote.RemoteTestNG.initAndRun(RemoteTestNG.java:137)
	at org.testng.remote.RemoteTestNG.main(RemoteTestNG.java:58)
]]>
            </full-stacktrace>
          </exception> <!-- junit.framework.AssertionFailedError -->
          <reporter-output>
          </reporter-output>
        </test-method> <!-- Test2 -->
        <test-method status="FAIL" signature="Test2()[pri:0, instance:usingretryAnalyzer.MyTest@7946e1f4]" name="Test2" duration-ms="4" started-at="2020-08-22T15:13:45Z" finished-at="2020-08-22T15:13:45Z">
          <exception class="junit.framework.AssertionFailedError">
            <message>
              <![CDATA[expected:<false> but was:<true>]]>
            </message>
            <full-stacktrace>
              <![CDATA[junit.framework.AssertionFailedError: expected:<false> but was:<true>
	at junit.framework.Assert.fail(Assert.java:47)
	at junit.framework.Assert.failNotEquals(Assert.java:282)
	at junit.framework.Assert.assertEquals(Assert.java:64)
	at junit.framework.Assert.assertEquals(Assert.java:149)
	at junit.framework.Assert.assertEquals(Assert.java:155)
	at usingretryAnalyzer.MyTest.Test2(MyTest.java:16)
	at sun.reflect.NativeMethodAccessorImpl.invoke0(Native Method)
	at sun.reflect.NativeMethodAccessorImpl.invoke(Unknown Source)
	at sun.reflect.DelegatingMethodAccessorImpl.invoke(Unknown Source)
	at java.lang.reflect.Method.invoke(Unknown Source)
	at org.testng.internal.MethodInvocationHelper.invokeMethod(MethodInvocationHelper.java:86)
	at org.testng.internal.Invoker.invokeMethod(Invoker.java:646)
	at org.testng.internal.Invoker.retryFailed(Invoker.java:970)
	at org.testng.internal.Invoker.invokeTestMethods(Invoker.java:1149)
	at org.testng.internal.TestMethodWorker.invokeTestMethods(TestMethodWorker.java:129)
	at org.testng.internal.TestMethodWorker.run(TestMethodWorker.java:112)
	at org.testng.TestRunner.privateRun(TestRunner.java:778)
	at org.testng.TestRunner.run(TestRunner.java:632)
	at org.testng.SuiteRunner.runTest(SuiteRunner.java:366)
	at org.testng.SuiteRunner.runSequentially(SuiteRunner.java:361)
	at org.testng.SuiteRunner.privateRun(SuiteRunner.java:319)
	at org.testng.SuiteRunner.run(SuiteRunner.java:268)
	at org.testng.SuiteRunnerWorker.runSuite(SuiteRunnerWorker.java:52)
	at org.testng.SuiteRunnerWorker.run(SuiteRunnerWorker.java:86)
	at org.testng.TestNG.runSuitesSequentially(TestNG.java:1225)
	at org.testng.TestNG.runSuitesLocally(TestNG.java:1150)
	at org.testng.TestNG.runSuites(TestNG.java:1075)
	at org.testng.TestNG.run(TestNG.java:1047)
	at org.testng.remote.AbstractRemoteTestNG.run(AbstractRemoteTestNG.java:126)
	at org.testng.remote.RemoteTestNG.initAndRun(RemoteTestNG.java:137)
	at org.testng.remote.RemoteTestNG.main(RemoteTestNG.java:58)
]]>
            </full-stacktrace>
          </exception> <!-- junit.framework.AssertionFailedError -->
          <reporter-output>
          </reporter-output>
        </test-method> <!-- Test2 -->
      </class> <!-- usingretryAnalyzer.MyTest -->
    </test> <!-- Default test -->
  </suite> <!-- Default suite -->
</testng-results>
